Workbook

Sheet Piano Investimenti 24 Mesi
A1: PRIVATIO — Piano Finanziario Investimenti 24 Mesi
A2: Business Plan per domanda ON — Oltre Nuove Imprese a Tasso Zero
A4: Voce di Costo | B4: Mese 1 | C4: Mese 2 | D4: Mese 3 | E4: Mese 4 | F4: Mese 5 | G4: Mese 6 | H4: Mese 7 | I4: Mese 8 | J4: Mese 9 | K4: Mese 10 | L4: Mese 11 | M4: Mese 12 | N4: Mese 13 | O4: Mese 14 | P4: Mese 15 | Q4: Mese 16 | R4: Mese 17 | S4: Mese 18 | T4: Mese 19 | U4: Mese 20 | V4: Mese 21 | W4: Mese 22 | X4: Mese 23 | Y4: Mese 24 | Z4: TOT Anno 1 | AA4: TOT Anno 2
A5: PERSONALE & COLLABORATORI
A6: Compenso Amministratore (Federico) | B6: 2000 | C6: 2000 | D6: 2000 | E6: 2000 | F6: 2000 | G6: 2000 | H6: 2000 | I6: 2000 | J6: 2000 | K6: 2000 | L6: 2000 | M6: 2000 | N6: 2000 | O6: 2000 | P6: 2000 | Q6: 2000 | R6: 2000 | S6: 2000 | T6: 2000 | U6: 2000 | V6: 2000 | W6: 2000 | X6: 2000 | Y6: 2000 | Z6: =SUM(B6:M6) -> 24000 | AA6: =SUM(N6:Y6) -> 24000
A7: Risorse tecniche — sviluppo e manutenzione piattaforma | B7: 0 | C7: 0 | D7: 4200 | E7: 4200 | F7: 4200 | G7: 4200 | H7: 4200 | I7: 4200 | J7: 4200 | K7: 4200 | L7: 4200 | M7: 4200 | N7: 4200 | O7: 4200 | P7: 4200 | Q7: 4200 | R7: 4200 | S7: 4200 | T7: 4200 | U7: 4200 | V7: 4200 | W7: 4200 | X7: 4200 | Y7: 4200 | Z7: =SUM(B7:M7) -> 42000 | AA7: =SUM(N7:Y7) -> 50400
A8: Risorse operative — gestione clienti e agenzie | B8: 0 | C8: 0 | D8: 0 | E8: 1200 | F8: 1200 | G8: 1200 | H8: 1200 | I8: 1200 | J8: 1200 | K8: 1200 | L8: 1200 | M8: 1200 | N8: 2200 | O8: 2200 | P8: 2200 | Q8: 2200 | R8: 2200 | S8: 2200 | T8: 2200 | U8: 2200 | V8: 2200 | W8: 2200 | X8: 2200 | Y8: 2200 | Z8: =SUM(B8:M8) -> 10800 | AA8: =SUM(N8:Y8) -> 26400
A9: Risorse commerciali — sviluppo rete vendita | B9: 0 | C9: 0 | D9: 0 | E9: 0 | F9: 0 | G9: 0 | H9: 500 | I9: 500 | J9: 500 | K9: 500 | L9: 500 | M9: 500 | N9: 1000 | O9: 1000 | P9: 1000 | Q9: 1000 | R9: 1000 | S9: 1000 | T9: 1000 | U9: 1000 | V9: 1000 | W9: 1000 | X9: 1000 | Y9: 1000 | Z9: =SUM(B9:M9) -> 3000 | AA9: =SUM(N9:Y9) -> 12000
A10: Subtotale PERSONALE & COLLABORATORI | B10: =B6+B7+B8+B9 -> 2000 | C10: =C6+C7+C8+C9 -> 2000 | D10: =D6+D7+D8+D9 -> 6200 | E10: =E6+E7+E8+E9 -> 7400 | F10: =F6+F7+F8+F9 -> 7400 | G10: =G6+G7+G8+G9 -> 7400 | H10: =H6+H7+H8+H9 -> 7900 | I10: =I6+I7+I8+I9 -> 7900 | ... AA10: =AA6+AA7+AA8+AA9 -> 112800
A12: MARKETING
A13: Campagne Ads (Meta, Google, TikTok) | B13: 1500 | C13: 1500 | D13: 1500 | E13: 2500 | F13: 2500 | G13: 2500 | H13: 3500 | I13: 3500 | J13: 3500 | K13: 3500 | L13: 3500 | M13: 3500 | N13: 4500 | O13: 4500 | P13: 4500 | Q13: 4500 | R13: 4500 | S13: 4500 | T13: 5500 | U13: 5500 | V13: 5500 | W13: 5500 | X13: 5500 | Y13: 5500 | Z13: =SUM(B13:M13) -> 33000 | AA13: =SUM(N13:Y13) -> 60000
A14: Content Creation (foto, video, grafiche) | B14: 2000 | C14: 1000 | D14: 1000 | E14: 1000 | F14: 1000 | G14: 1000 | H14: 1500 | I14: 1500 | J14: 1500 | K14: 1500 | L14: 1500 | M14: 1500 | N14: 1500 | O14: 1500 | P14: 1500 | Q14: 1500 | R14: 1500 | S14: 1500 | T14: 1500 | U14: 1500 | V14: 1500 | W14: 1500 | X14: 1500 | Y14: 1500 | Z14: =SUM(B14:M14) -> 16000 | AA14: =SUM(N14:Y14) -> 18000
A15: Influencer & Partnership | B15: 0 | C15: 0 | D15: 1500 | E15: 1500 | F15: 1500 | G15: 1500 | H15: 2000 | I15: 2000 | J15: 2000 | K15: 2000 | L15: 2000 | M15: 2000 | N15: 2500 | O15: 2500 | P15: 2500 | Q15: 2500 | R15: 2500 | S15: 2500 | T15: 2500 | U15: 2500 | V15: 2500 | W15: 2500 | X15: 2500 | Y15: 2500 | Z15: =SUM(B15:M15) -> 18000 | AA15: =SUM(N15:Y15) -> 30000
A16: SEO & Content Marketing | B16: 500 | C16: 500 | D16: 500 | E16: 500 | F16: 500 | G16: 500 | H16: 800 | I16: 800 | J16: 800 | K16: 800 | L16: 800 | M16: 800 | N16: 1000 | O16: 1000 | P16: 1000 | Q16: 1000 | R16: 1000 | S16: 1000 | T16: 1000 | U16: 1000 | V16: 1000 | W16: 1000 | X16: 1000 | Y16: 1000 | Z16: =SUM(B16:M16) -> 7800 | AA16: =SUM(N16:Y16) -> 12000
A17: Branding & Materiali Comunicazione | B17: 3000 | C17: 500 | D17: 500 | E17: 500 | F17: 500 | G17: 500 | H17: 300 | I17: 300 | J17: 300 | K17: 300 | L17: 300 | M17: 300 | N17: 300 | O17: 300 | P17: 300 | Q17: 300 | R17: 300 | S17: 300 | T17: 300 | U17: 300 | V17: 300 | W17: 300 | X17: 300 | Y17: 300 | Z17: =SUM(B17:M17) -> 7300 | AA17: =SUM(N17:Y17) -> 3600
A18: Eventi & Fiere Immobiliari | B18: 0 | C18: 0 | D18: 0 | E18: 0 | F18: 0 | G18: 2000 | H18: 0 | I18: 0 | J18: 0 | K18: 0 | L18: 0 | M18: 2000 | N18: 1500 | O18: 1500 | P18: 1500 | Q18: 1500 | R18: 1500 | S18: 1500 | T18: 0 | U18: 0 | V18: 0 | W18: 1500 | X18: 0 | Y18: 1500 | Z18: =SUM(B18:M18) -> 4000 | AA18: =SUM(N18:Y18) -> 12000
A19: Subtotale MARKETING | B19: =B13+B14+B15+B16+B17+B18 -> 7000 | C19: =C13+C14+C15+C16+C17+C18 -> 3500 | D19: =D13+D14+D15+D16+D17+D18 -> 5000 | E19: =E13+E14+E15+E16+E17+E18 -> 6000 | F19: =F13+F14+F15+F16+F17+F18 -> 6000 | G19: =G13+G14+G15+G16+G17+G18 -> 8000 | H19: =H13+H14+H15+H16+H17+H18 -> 8100 | I19: =I13+I14+I15+I16+I17+I18 -> 8100 | ... AA19: =AA13+AA14+AA15+AA16+AA17+AA18 -> 135600
A21: INFRASTRUTTURA TECH
A22: Hosting (Vercel Pro) | B22: 20 | C22: 20 | D22: 20 | E22: 20 | F22: 20 | G22: 20 | H22: 20 | I22: 20 | J22: 20 | K22: 20 | L22: 20 | M22: 20 | N22: 20 | O22: 20 | P22: 20 | Q22: 20 | R22: 20 | S22: 20 | T22: 20 | U22: 20 | V22: 20 | W22: 20 | X22: 20 | Y22: 20 | Z22: =SUM(B22:M22) -> 240 | AA22: =SUM(N22:Y22) -> 240
A23: Database (Supabase Pro) | B23: 25 | C23: 25 | D23: 25 | E23: 25 | F23: 25 | G23: 25 | H23: 25 | I23: 25 | J23: 25 | K23: 25 | L23: 25 | M23: 25 | N23: 25 | O23: 25 | P23: 25 | Q23: 25 | R23: 25 | S23: 25 | T23: 25 | U23: 25 | V23: 25 | W23: 25 | X23: 25 | Y23: 25 | Z23: =SUM(B23:M23) -> 300 | AA23: =SUM(N23:Y23) -> 300
A24: Dominio & DNS | B24: 50 | C24: 0 | D24: 0 | E24: 0 | F24: 0 | G24: 0 | H24: 0 | I24: 0 | J24: 0 | K24: 0 | L24: 0 | M24: 0 | N24: 50 | O24: 0 | P24: 0 | Q24: 0 | R24: 0 | S24: 0 | T24: 0 | U24: 0 | V24: 0 | W24: 0 | X24: 0 | Y24: 0 | Z24: =SUM(B24:M24) -> 50 | AA24: =SUM(N24:Y24) -> 50
A25: Stripe (commissioni stimate) | B25: 0 | C25: 0 | D25: 0 | E25: 50 | F25: 50 | G25: 50 | H25: 100 | I25: 100 | J25: 100 | K25: 100 | L25: 100 | M25: 100 | N25: 200 | O25: 200 | P25: 200 | Q25: 200 | R25: 200 | S25: 200 | T25: 200 | U25: 200 | V25: 200 | W25: 200 | X25: 200 | Y25: 200 | Z25: =SUM(B25:M25) -> 750 | AA25: =SUM(N25:Y25) -> 2400
A26: Email Service (Resend) | B26: 20 | C26: 20 | D26: 20 | E26: 20 | F26: 20 | G26: 20 | H26: 20 | I26: 20 | J26: 20 | K26: 20 | L26: 20 | M26: 20 | N26: 20 | O26: 20 | P26: 20 | Q26: 20 | R26: 20 | S26: 20 | T26: 20 | U26: 20 | V26: 20 | W26: 20 | X26: 20 | Y26: 20 | Z26: =SUM(B26:M26) -> 240 | AA26: =SUM(N26:Y26) -> 240
A27: Tool & Licenze Software | B27: 100 | C27: 100 | D27: 100 | E27: 100 | F27: 100 | G27: 100 | H27: 100 | I27: 100 | J27: 100 | K27: 100 | L27: 100 | M27: 100 | N27: 150 | O27: 150 | P27: 150 | Q27: 150 | R27: 150 | S27: 150 | T27: 150 | U27: 150 | V27: 150 | W27: 150 | X27: 150 | Y27: 150 | Z27: =SUM(B27:M27) -> 1200 | AA27: =SUM(N27:Y27) -> 1800
A28: Monitoring & Analytics | B28: 50 | C28: 50 | D28: 50 | E28: 50 | F28: 50 | G28: 50 | H28: 50 | I28: 50 | J28: 50 | K28: 50 | L28: 50 | M28: 50 | N28: 50 | O28: 50 | P28: 50 | Q28: 50 | R28: 50 | S28: 50 | T28: 50 | U28: 50 | V28: 50 | W28: 50 | X28: 50 | Y28: 50 | Z28: =SUM(B28:M28) -> 600 | AA28: =SUM(N28:Y28) -> 600
A29: Subtotale INFRASTRUTTURA TECH | B29: =B22+B23+B24+B25+B26+B27+B28 -> 265 | C29: =C22+C23+C24+C25+C26+C27+C28 -> 215 | D29: =D22+D23+D24+D25+D26+D27+D28 -> 215 | E29: =E22+E23+E24+E25+E26+E27+E28 -> 265 | F29: =F22+F23+F24+F25+F26+F27+F28 -> 265 | G29: =G22+G23+G24+G25+G26+G27+G28 -> 265 | H29: =H22+H23+H24+H25+H26+H27+H28 -> 315 | I29: =I22+I23+I24+I25+I26+I27+I28 -> 315 | ... AA29: =AA22+AA23+AA24+AA25+AA26+AA27+AA28 -> 5630
A31: CONSULENZE & SERVIZI
A32: Commercialista | B32: 300 | C32: 300 | D32: 300 | E32: 300 | F32: 300 | G32: 300 | H32: 300 | I32: 300 | J32: 300 | K32: 300 | L32: 300 | M32: 300 | N32: 300 | O32: 300 | P32: 300 | Q32: 300 | R32: 300 | S32: 300 | T32: 300 | U32: 300 | V32: 300 | W32: 300 | X32: 300 | Y32: 300 | Z32: =SUM(B32:M32) -> 3600 | AA32: =SUM(N32:Y32) -> 3600
A33: Consulente del Lavoro | B33: 0 | C33: 0 | D33: 200 | E33: 200 | F33: 200 | G33: 200 | H33: 200 | I33: 200 | J33: 200 | K33: 200 | L33: 200 | M33: 200 | N33: 200 | O33: 200 | P33: 200 | Q33: 200 | R33: 200 | S33: 200 | T33: 200 | U33: 200 | V33: 200 | W33: 200 | X33: 200 | Y33: 200 | Z33: =SUM(B33:M33) -> 2000 | AA33: =SUM(N33:Y33) -> 2400
A34: Assistenza Legale | B34: 2000 | C34: 500 | D34: 500 | E34: 500 | F34: 500 | G34: 500 | H34: 300 | I34: 300 | J34: 300 | K34: 300 | L34: 300 | M34: 300 | N34: 400 | O34: 400 | P34: 400 | Q34: 400 | R34: 400 | S34: 400 | T34: 400 | U34: 400 | V34: 400 | W34: 400 | X34: 400 | Y34: 400 | Z34: =SUM(B34:M34) -> 6300 | AA34: =SUM(N34:Y34) -> 4800
A35: Assicurazioni (RC, D&O) | B35: 250 | C35: 250 | D35: 250 | E35: 250 | F35: 250 | G35: 250 | H35: 250 | I35: 250 | J35: 250 | K35: 250 | L35: 250 | M35: 250 | N35: 250 | O35: 250 | P35: 250 | Q35: 250 | R35: 250 | S35: 250 | T35: 250 | U35: 250 | V35: 250 | W35: 250 | X35: 250 | Y35: 250 | Z35: =SUM(B35:M35) -> 3000 | AA35: =SUM(N35:Y35) -> 3000
A36: Subtotale CONSULENZE & SERVIZI | B36: =B32+B33+B34+B35 -> 2550 | C36: =C32+C33+C34+C35 -> 1050 | D36: =D32+D33+D34+D35 -> 1250 | E36: =E32+E33+E34+E35 -> 1250 | F36: =F32+F33+F34+F35 -> 1250 | G36: =G32+G33+G34+G35 -> 1250 | H36: =H32+H33+H34+H35 -> 1050 | I36: =I32+I33+I34+I35 -> 1050 | ... AA36: =AA32+AA33+AA34+AA35 -> 13800
A38: COSTI GENERALI
A39: Ufficio / Coworking | B39: 300 | C39: 300 | D39: 300 | E39: 300 | F39: 300 | G39: 300 | H39: 300 | I39: 300 | J39: 300 | K39: 300 | L39: 300 | M39: 300 | N39: 300 | O39: 300 | P39: 300 | Q39: 300 | R39: 300 | S39: 300 | T39: 300 | U39: 300 | V39: 300 | W39: 300 | X39: 300 | Y39: 300 | Z39: =SUM(B39:M39) -> 3600 | AA39: =SUM(N39:Y39) -> 3600
A40: Costi Bancari | B40: 40 | C40: 40 | D40: 40 | E40: 40 | F40: 40 | G40: 40 | H40: 40 | I40: 40 | J40: 40 | K40: 40 | L40: 40 | M40: 40 | N40: 40 | O40: 40 | P40: 40 | Q40: 40 | R40: 40 | S40: 40 | T40: 40 | U40: 40 | V40: 40 | W40: 40 | X40: 40 | Y40: 40 | Z40: =SUM(B40:M40) -> 480 | AA40: =SUM(N40:Y40) -> 480
A41: Software Gestionale / Fatturazione | B41: 50 | C41: 50 | D41: 50 | E41: 50 | F41: 50 | G41: 50 | H41: 50 | I41: 50 | J41: 50 | K41: 50 | L41: 50 | M41: 50 | N41: 50 | O41: 50 | P41: 50 | Q41: 50 | R41: 50 | S41: 50 | T41: 50 | U41: 50 | V41: 50 | W41: 50 | X41: 50 | Y41: 50 | Z41: =SUM(B41:M41) -> 600 | AA41: =SUM(N41:Y41) -> 600
A42: Formazione & Aggiornamento | B42: 100 | C42: 100 | D42: 100 | E42: 100 | F42: 100 | G42: 100 | H42: 100 | I42: 100 | J42: 100 | K42: 100 | L42: 100 | M42: 100 | N42: 100 | O42: 100 | P42: 100 | Q42: 100 | R42: 100 | S42: 100 | T42: 100 | U42: 100 | V42: 100 | W42: 100 | X42: 100 | Y42: 100 | Z42: =SUM(B42:M42) -> 1200 | AA42: =SUM(N42:Y42) -> 1200
A43: Trasferte | B43: 100 | C43: 100 | D43: 100 | E43: 100 | F43: 100 | G43: 100 | H43: 100 | I43: 100 | J43: 100 | K43: 100 | L43: 100 | M43: 100 | N43: 200 | O43: 200 | P43: 200 | Q43: 200 | R43: 200 | S43: 200 | T43: 200 | U43: 200 | V43: 200 | W43: 200 | X43: 200 | Y43: 200 | Z43: =SUM(B43:M43) -> 1200 | AA43: =SUM(N43:Y43) -> 2400
A44: Imprevisti (5% costi operativi) | B44: =(B6+B7+B8+B9+B13+B14+B15+B16+B17+B18+B22+B23+B24+B25+B26+B27+B28+B32+B33+B34+B35+B39+B40+B41+B42+B43)*0.05 -> 620.25 | C44: =(C6+C7+C8+C9+C13+C14+C15+C16+C17+C18+C22+C23+C24+C25+C26+C27+C28+C32+C33+C34+C35+C39+C40+C41+C42+C43)*0.05 -> 367.75 | D44: =(D6+D7+D8+D9+D13+D14+D15+D16+D17+D18+D22+D23+D24+D25+D26+D27+D28+D32+D33+D34+D35+D39+D40+D41+D42+D43)*0.05 -> 662.75 | E44: =(E6+E7+E8+E9+E13+E14+E15+E16+E17+E18+E22+E23+E24+E25+E26+E27+E28+E32+E33+E34+E35+E39+E40+E41+E42+E43)*0.05 -> 775.25 | F44: =(F6+F7+F8+F9+F13+F14+F15+F16+F17+F18+F22+F23+F24+F25+F26+F27+F28+F32+F33+F34+F35+F39+F40+F41+F42+F43)*0.05 -> 775.25 | G44: =(G6+G7+G8+G9+G13+G14+G15+G16+G17+G18+G22+G23+G24+G25+G26+G27+G28+G32+G33+G34+G35+G39+G40+G41+G42+G43)*0.05 -> 875.25 | H44: =(H6+H7+H8+H9+H13+H14+H15+H16+H17+H18+H22+H23+H24+H25+H26+H27+H28+H32+H33+H34+H35+H39+H40+H41+H42+H43)*0.05 -> 897.75 | I44: =(I6+I7+I8+I9+I13+I14+I15+I16+I17+I18+I22+I23+I24+I25+I26+I27+I28+I32+I33+I34+I35+I39+I40+I41+I42+I43)*0.05 -> 897.75 | ... AA44: =(AA6+AA7+AA8+AA9+AA13+AA14+AA15+AA16+AA17+AA18+AA22+AA23+AA24+AA25+AA26+AA27+AA28+AA32+AA33+AA34+AA35+AA39+AA40+AA41+AA42+AA43)*0.05 -> 13805.5
A45: Subtotale COSTI GENERALI | B45: =B39+B40+B41+B42+B43+B44 -> 1210.25 | C45: =C39+C40+C41+C42+C43+C44 -> 957.75 | D45: =D39+D40+D41+D42+D43+D44 -> 1252.75 | E45: =E39+E40+E41+E42+E43+E44 -> 1365.25 | F45: =F39+F40+F41+F42+F43+F44 -> 1365.25 | G45: =G39+G40+G41+G42+G43+G44 -> 1465.25 | H45: =H39+H40+H41+H42+H43+H44 -> 1487.75 | I45: =I39+I40+I41+I42+I43+I44 -> 1487.75 | ... AA45: =AA39+AA40+AA41+AA42+AA43+AA44 -> 22085.5
...

Sheet Riepilogo Agevolazione
A1: RIEPILOGO INVESTIMENTO & STRUTTURA AGEVOLAZIONE ON
A3: Categoria | B3: Anno 1 | C3: Anno 2 | D3: Totale
A4: Personale | B4: ='Piano Investimenti 24 Mesi'!Z10 -> 79800 | C4: ='Piano Investimenti 24 Mesi'!AA10 -> 112800 | D4: =B4+C4 -> 192600
A5: Marketing | B5: ='Piano Investimenti 24 Mesi'!Z19 -> 86100 | C5: ='Piano Investimenti 24 Mesi'!AA19 -> 135600 | D5: =B5+C5 -> 221700
A6: Infrastruttura Tech | B6: ='Piano Investimenti 24 Mesi'!Z29 -> 3380 | C6: ='Piano Investimenti 24 Mesi'!AA29 -> 5630 | D6: =B6+C6 -> 9010
A7: Consulenze & Servizi | B7: ='Piano Investimenti 24 Mesi'!Z36 -> 14900 | C7: ='Piano Investimenti 24 Mesi'!AA36 -> 13800 | D7: =B7+C7 -> 28700
A8: Costi Generali | B8: ='Piano Investimenti 24 Mesi'!Z45 -> 16643 | C8: ='Piano Investimenti 24 Mesi'!AA45 -> 22085.5 | D8: =B8+C8 -> 38728.5
A9: TOTALE INVESTIMENTO | B9: =SUM(B4:B8) -> 200823 | C9: =SUM(C4:C8) -> 289915.5 | D9: =SUM(D4:D8) -> 490738.5
A11: STRUTTURA AGEVOLAZIONE ON
A12: Voce | B12: % | C12: Importo | D12: Note
A13: Copertura agevolazione | B13: 90% | C13: =D9*0.9 -> 441664.65 | D13: Massimo ammissibile
A14: Contributo a Fondo Perduto (20%) | B14: 20% | C14: =D9*0.9*0.2 -> 88332.93 | D14: Non va restituito
A15: Finanziamento a Tasso Zero (80%) | B15: 80% | C15: =D9*0.9*0.8 -> 353331.72 | D15: Da restituire in 10 anni
A16: Quota a carico dell'impresa (10%) | B16: 10% | C16: =D9*0.1 -> 49073.85 | D16: Mezzi propri o altro

Sheet Simulazione Rimborso
A1: SIMULAZIONE RIMBORSO FINANZIAMENTO A TASSO ZERO — 10 ANNI
A2: Rate semestrali costanti posticipate (31 maggio e 30 novembre)
A4: Parametri
A5: Importo finanziamento: | B5: ='Riepilogo Agevolazione'!C15 -> 353331.72
A6: Durata (anni): | B6: 10
A7: N° rate semestrali: | B7: =B6*2 -> 20
A8: Importo singola rata: | B8: =B5/B7 -> 17666.586
A9: Equivalente mensile: | B9: =B8/6 -> 2944.431
A11: Rata N° | B11: Scadenza | C11: Importo Rata | D11: Capitale Rimborsato | E11: Debito Residuo
A12: 1 | B12: 46356 | C12: =$B$8 -> 17666.586 | D12: =C12*1 -> 17666.586 | E12: =$B$5-D12 -> 335665.13
A13: 2 | B13: 46538 | C13: =$B$8 -> 17666.586 | D13: =C13*2 -> 35333.172 | E13: =$B$5-D13 -> 317998.55
A14: 3 | B14: 46721 | C14: =$B$8 -> 17666.586 | D14: =C14*3 -> 52999.758 | E14: =$B$5-D14 -> 300331.96
A15: 4 | B15: 46904 | C15: =$B$8 -> 17666.586 | D15: =C15*4 -> 70666.344 | E15: =$B$5-D15 -> 282665.38
A16: 5 | B16: 47087 | C16: =$B$8 -> 17666.586 | D16: =C16*5 -> 88332.93 | E16: =$B$5-D16 -> 264998.79
A17: 6 | B17: 47269 | C17: =$B$8 -> 17666.586 | D17: =C17*6 -> 105999.52 | E17: =$B$5-D17 -> 247332.2
A18: 7 | B18: 47452 | C18: =$B$8 -> 17666.586 | D18: =C18*7 -> 123666.1 | E18: =$B$5-D18 -> 229665.62
A19: 8 | B19: 47634 | C19: =$B$8 -> 17666.586 | D19: =C19*8 -> 141332.69 | E19: =$B$5-D19 -> 211999.03
A20: 9 | B20: 47817 | C20: =$B$8 -> 17666.586 | D20: =C20*9 -> 158999.27 | E20: =$B$5-D20 -> 194332.45
A21: 10 | B21: 47999 | C21: =$B$8 -> 17666.586 | D21: =C21*10 -> 176665.86 | E21: =$B$5-D21 -> 176665.86
A22: 11 | B22: 48182 | C22: =$B$8 -> 17666.586 | D22: =C22*11 -> 194332.45 | E22: =$B$5-D22 -> 158999.27
A23: 12 | B23: 48365 | C23: =$B$8 -> 17666.586 | D23: =C23*12 -> 211999.03 | E23: =$B$5-D23 -> 141332.69
A24: 13 | B24: 48548 | C24: =$B$8 -> 17666.586 | D24: =C24*13 -> 229665.62 | E24: =$B$5-D24 -> 123666.1
A25: 14 | B25: 48730 | C25: =$B$8 -> 17666.586 | D25: =C25*14 -> 247332.2 | E25: =$B$5-D25 -> 105999.52
A26: 15 | B26: 48913 | C26: =$B$8 -> 17666.586 | D26: =C26*15 -> 264998.79 | E26: =$B$5-D26 -> 88332.93
A27: 16 | B27: 49095 | C27: =$B$8 -> 17666.586 | D27: =C27*16 -> 282665.38 | E27: =$B$5-D27 -> 70666.344
A28: 17 | B28: 49278 | C28: =$B$8 -> 17666.586 | D28: =C28*17 -> 300331.96 | E28: =$B$5-D28 -> 52999.758
A29: 18 | B29: 49460 | C29: =$B$8 -> 17666.586 | D29: =C29*18 -> 317998.55 | E29: =$B$5-D29 -> 35333.172
A30: 19 | B30: 49643 | C30: =$B$8 -> 17666.586 | D30: =C30*19 -> 335665.13 | E30: =$B$5-D30 -> 17666.586
A31: 20 | B31: 49826 | C31: =$B$8 -> 17666.586 | D31: =C31*20 -> 353331.72 | E31: =$B$5-D31 -> 0
